Workbook
Name AliasPaths: EpecBaseProject!$G$1:$G$960
Name ChannelPaths: EpecBaseProject!$H$1:$H$960

Sheet EpecBaseProject
A1: ATE I/O Ch | B1: ATE I/O Type | C1: Chassis Module/Ch | D1: Module Ch | E1: Channel I/O Configuration and type | F1: VeriStand Alias Name | G1: VeriStand Alias Path | H1: VeriStand Channel path | I1: ATE Alias Specifier | J1: ATE Mass Interconnect ODU BLACK Connector/pin | K1: ITA Enclosure ODU BLUE Connector/pin | L1: DUT Connector/Pin | M1: DUT HW Block | N1: DUT I/O Range
A2: 1 | B2: AO/DO AO U: 0-10 V DO: 0-Vsup | C2: ="PXIe-6738/AO" & D2 -> PXIe-6738/AO0 | D2: 0 | E2: Voltage out 0-10 V | F2: AO | G2: =IF(OR(F2="None",F2="TBD"),"None",_xlfn.CONCAT("ATE/",I2,"/",F2)) -> ATE/IO1/AO | H2: =Paths!$B$26 & D2 -> Targets/Controller/Hardware/Chassis/DAQ/PXI1Slot15/Analog Output/AO0 | I2: ="IO" & A2 -> IO1 | J2: A1.1 | K2: Bx.x
C3: ="PXIe-7820R/DIO" & D3 -> PXIe-7820R/DIO0 | D3: 0 | E3: FPGA DO (PWM Gen.) | F3: PWM_FR | G3: =IF(OR(F3="None",F3="TBD"),"None",_xlfn.CONCAT("ATE/",I3,"/",F3)) -> ATE/IO1/PWM_FR | H3: =Paths!$B$2 & I3 & Paths!$B$6 -> Targets/Controller/Custom Devices/FPGA Addon/Scalars/Scalar Outputs/PWM.Out.IO1/FREQ | I3: ="IO" & A2 -> IO1
C4: ="PXIe-7820R/DIO" & D4 -> PXIe-7820R/DIO0 | D4: 0 | E4: FPGA DO (PWM Gen.) | F4: PWM_DC | G4: =IF(OR(F4="None",F4="TBD"),"None",_xlfn.CONCAT("ATE/",I4,"/",F4)) -> ATE/IO1/PWM_DC | H4: =Paths!$B$2 & I4 & Paths!$B$7 -> Targets/Controller/Custom Devices/FPGA Addon/Scalars/Scalar Outputs/PWM.Out.IO1/DC | I4: ="IO" & A2 -> IO1
C5: ="SLSC-12201-1/P" & ROUNDDOWN(D5/8,0) & "." & MOD(D5,8) -> SLSC-12201-1/P0.0 | D5: 0 | E5: Output Push-Pull | F5: None | G5: =IF(OR(F5="None",F5="TBD"),"None",_xlfn.CONCAT("ATE/",I5,"/",F5)) -> None | H5: =Paths!$B$19 & "Bank " & ROUNDDOWN(D5/16,0) & "/Port " & ROUNDDOWN(D5/8,0) & "/Line " &MOD(D5,8) &"/Direction" -> Targets/Controller/Hardware/SLSC/SLSC Chassis/Modules/Slot 8 (SLSC-12201 DIO)/Bank 0/Port 0/Line 0/Direction | I5: ="IO" & A2 -> IO1
C6: ="PXI 10-100-001/SPDT" & D6 -> PXI 10-100-001/SPDT1 | D6: 1 | E6: DO (SPDT) | F6: Select_DO | G6: =IF(OR(F6="None",F6="TBD"),"None",_xlfn.CONCAT("ATE/",I6,"/",F6)) -> ATE/IO1/Select_DO | H6: =Paths!$B$12 & D6 -> Targets/Controller/Custom Devices/PickeringSwitching/Subunit1/Switch1_1 | I6: ="IO" & A2 -> IO1
C7: ="PXI-2510-1/dut" & D7 -> PXI-2510-1/dut0 | D7: 0 | E7: FIU | F7: TBD | G7: =IF(OR(F7="None",F7="TBD"),"None",_xlfn.CONCAT("ATE/",I7,"/",F7)) -> None | H7: TBD | I7: ="IO" & A2 -> IO1
A8: =A2+1 -> 2 | B8: =B2 -> AO/DO AO U: 0-10 V DO: 0-Vsup | C8: ="PXIe-6738/AO" & D8 -> PXIe-6738/AO1 | D8: =D2+1 -> 1 | E8: =E2 -> Voltage out 0-10 V | F8: =F2 -> AO | G8: =IF(OR(F8="None",F8="TBD"),"None",_xlfn.CONCAT("ATE/",I8,"/",F8)) -> ATE/IO2/AO | H8: =Paths!$B$26 & D8 -> Targets/Controller/Hardware/Chassis/DAQ/PXI1Slot15/Analog Output/AO1 | I8: ="IO" & A8 -> IO2 | J8: Ax.x | K8: Bx.x
C9: ="PXIe-7820R/DIO" & D9 -> PXIe-7820R/DIO1 | D9: =D3+1 -> 1 | E9: =E3 -> FPGA DO (PWM Gen.) | F9: =F3 -> PWM_FR | G9: =IF(OR(F9="None",F9="TBD"),"None",_xlfn.CONCAT("ATE/",I9,"/",F9)) -> ATE/IO2/PWM_FR | H9: =Paths!$B$2 & I9 & Paths!$B$6 -> Targets/Controller/Custom Devices/FPGA Addon/Scalars/Scalar Outputs/PWM.Out.IO2/FREQ | I9: ="IO" & A8 -> IO2
C10: ="PXIe-7820R/DIO" & D10 -> PXIe-7820R/DIO1 | D10: =D4+1 -> 1 | E10: =E4 -> FPGA DO (PWM Gen.) | F10: =F4 -> PWM_DC | G10: =IF(OR(F10="None",F10="TBD"),"None",_xlfn.CONCAT("ATE/",I10,"/",F10)) -> ATE/IO2/PWM_DC | H10: =Paths!$B$2 & I10 & Paths!$B$7 -> Targets/Controller/Custom Devices/FPGA Addon/Scalars/Scalar Outputs/PWM.Out.IO2/DC | I10: ="IO" & A8 -> IO2
C11: ="SLSC-12201-1/P" & ROUNDDOWN(D11/8,0) & "." & MOD(D11,8) -> SLSC-12201-1/P0.1 | D11: =D5+1 -> 1 | E11: =E5 -> Output Push-Pull | F11: =F5 -> None | G11: =IF(OR(F11="None",F11="TBD"),"None",_xlfn.CONCAT("ATE/",I11,"/",F11)) -> None | H11: =Paths!$B$19 & "Bank " & ROUNDDOWN(D11/16,0) & "/Port " & ROUNDDOWN(D11/8,0) & "/Line " &MOD(D11,8) &"/Direction" -> Targets/Controller/Hardware/SLSC/SLSC Chassis/Modules/Slot 8 (SLSC-12201 DIO)/Bank 0/Port 0/Line 1/Direction | I11: ="IO" & A8 -> IO2
C12: ="PXI 10-100-001/SPDT" & D12 -> PXI 10-100-001/SPDT2 | D12: =D6+1 -> 2 | E12: =E6 -> DO (SPDT) | F12: =F6 -> Select_DO | G12: =IF(OR(F12="None",F12="TBD"),"None",_xlfn.CONCAT("ATE/",I12,"/",F12)) -> ATE/IO2/Select_DO | H12: =Paths!$B$12 & D12 -> Targets/Controller/Custom Devices/PickeringSwitching/Subunit1/Switch1_2 | I12: ="IO" & A8 -> IO2
C13: ="PXI-2510-1/dut" & D13 -> PXI-2510-1/dut1 | D13: =D7+1 -> 1 | E13: =E7 -> FIU | F13: =F7 -> TBD | G13: =IF(OR(F13="None",F13="TBD"),"None",_xlfn.CONCAT("ATE/",I13,"/",F13)) -> None | H13: TBD | I13: ="IO" & A8 -> IO2
A14: =A8+1 -> 3 | B14: =B8 -> AO/DO AO U: 0-10 V DO: 0-Vsup | C14: ="PXIe-6738/AO" & D14 -> PXIe-6738/AO2 | D14: =D8+1 -> 2 | E14: =E8 -> Voltage out 0-10 V | F14: =F8 -> AO | G14: =IF(OR(F14="None",F14="TBD"),"None",_xlfn.CONCAT("ATE/",I14,"/",F14)) -> ATE/IO3/AO | H14: =Paths!$B$26 & D14 -> Targets/Controller/Hardware/Chassis/DAQ/PXI1Slot15/Analog Output/AO2 | I14: ="IO" & A14 -> IO3 | J14: Ax.x | K14: Bx.x
C15: ="PXIe-7820R/DIO" & D15 -> PXIe-7820R/DIO2 | D15: =D9+1 -> 2 | E15: =E9 -> FPGA DO (PWM Gen.) | F15: =F9 -> PWM_FR | G15: =IF(OR(F15="None",F15="TBD"),"None",_xlfn.CONCAT("ATE/",I15,"/",F15)) -> ATE/IO3/PWM_FR | H15: =Paths!$B$2 & I15 & Paths!$B$6 -> Targets/Controller/Custom Devices/FPGA Addon/Scalars/Scalar Outputs/PWM.Out.IO3/FREQ | I15: ="IO" & A14 -> IO3
C16: ="PXIe-7820R/DIO" & D16 -> PXIe-7820R/DIO2 | D16: =D10+1 -> 2 | E16: =E10 -> FPGA DO (PWM Gen.) | F16: =F10 -> PWM_DC | G16: =IF(OR(F16="None",F16="TBD"),"None",_xlfn.CONCAT("ATE/",I16,"/",F16)) -> ATE/IO3/PWM_DC | H16: =Paths!$B$2 & I16 & Paths!$B$7 -> Targets/Controller/Custom Devices/FPGA Addon/Scalars/Scalar Outputs/PWM.Out.IO3/DC | I16: ="IO" & A14 -> IO3
C17: ="SLSC-12201-1/P" & ROUNDDOWN(D17/8,0) & "." & MOD(D17,8) -> SLSC-12201-1/P0.2 | D17: =D11+1 -> 2 | E17: =E11 -> Output Push-Pull | F17: =F11 -> None | G17: =IF(OR(F17="None",F17="TBD"),"None",_xlfn.CONCAT("ATE/",I17,"/",F17)) -> None | H17: =Paths!$B$19 & "Bank " & ROUNDDOWN(D17/16,0) & "/Port " & ROUNDDOWN(D17/8,0) & "/Line " &MOD(D17,8) &"/Direction" -> Targets/Controller/Hardware/SLSC/SLSC Chassis/Modules/Slot 8 (SLSC-12201 DIO)/Bank 0/Port 0/Line 2/Direction | I17: ="IO" & A14 -> IO3
C18: ="PXI 10-100-001/SPDT" & D18 -> PXI 10-100-001/SPDT3 | D18: =D12+1 -> 3 | E18: =E12 -> DO (SPDT) | F18: =F12 -> Select_DO | G18: =IF(OR(F18="None",F18="TBD"),"None",_xlfn.CONCAT("ATE/",I18,"/",F18)) -> ATE/IO3/Select_DO | H18: =Paths!$B$12 & D18 -> Targets/Controller/Custom Devices/PickeringSwitching/Subunit1/Switch1_3 | I18: ="IO" & A14 -> IO3
C19: ="PXI-2510-1/dut" & D19 -> PXI-2510-1/dut2 | D19: =D13+1 -> 2 | E19: =E13 -> FIU | F19: =F13 -> TBD | G19: =IF(OR(F19="None",F19="TBD"),"None",_xlfn.CONCAT("ATE/",I19,"/",F19)) -> None | H19: TBD | I19: ="IO" & A14 -> IO3
A20: =A14+1 -> 4 | B20: =B14 -> AO/DO AO U: 0-10 V DO: 0-Vsup | C20: ="PXIe-6738/AO" & D20 -> PXIe-6738/AO3 | D20: =D14+1 -> 3 | E20: =E14 -> Voltage out 0-10 V | F20: =F14 -> AO | G20: =IF(OR(F20="None",F20="TBD"),"None",_xlfn.CONCAT("ATE/",I20,"/",F20)) -> ATE/IO4/AO | H20: =Paths!$B$26 & D20 -> Targets/Controller/Hardware/Chassis/DAQ/PXI1Slot15/Analog Output/AO3 | I20: ="IO" & A20 -> IO4 | J20: Ax.x | K20: Bx.x
C21: ="PXIe-7820R/DIO" & D21 -> PXIe-7820R/DIO3 | D21: =D15+1 -> 3 | E21: =E15 -> FPGA DO (PWM Gen.) | F21: =F15 -> PWM_FR | G21: =IF(OR(F21="None",F21="TBD"),"None",_xlfn.CONCAT("ATE/",I21,"/",F21)) -> ATE/IO4/PWM_FR | H21: =Paths!$B$2 & I21 & Paths!$B$6 -> Targets/Controller/Custom Devices/FPGA Addon/Scalars/Scalar Outputs/PWM.Out.IO4/FREQ | I21: ="IO" & A20 -> IO4
C22: ="PXIe-7820R/DIO" & D22 -> PXIe-7820R/DIO3 | D22: =D16+1 -> 3 | E22: =E16 -> FPGA DO (PWM Gen.) | F22: =F16 -> PWM_DC | G22: =IF(OR(F22="None",F22="TBD"),"None",_xlfn.CONCAT("ATE/",I22,"/",F22)) -> ATE/IO4/PWM_DC | H22: =Paths!$B$2 & I22 & Paths!$B$7 -> Targets/Controller/Custom Devices/FPGA Addon/Scalars/Scalar Outputs/PWM.Out.IO4/DC | I22: ="IO" & A20 -> IO4
C23: ="SLSC-12201-1/P" & ROUNDDOWN(D23/8,0) & "." & MOD(D23,8) -> SLSC-12201-1/P0.3 | D23: =D17+1 -> 3 | E23: =E17 -> Output Push-Pull | F23: =F17 -> None | G23: =IF(OR(F23="None",F23="TBD"),"None",_xlfn.CONCAT("ATE/",I23,"/",F23)) -> None | H23: =Paths!$B$19 & "Bank " & ROUNDDOWN(D23/16,0) & "/Port " & ROUNDDOWN(D23/8,0) & "/Line " &MOD(D23,8) &"/Direction" -> Targets/Controller/Hardware/SLSC/SLSC Chassis/Modules/Slot 8 (SLSC-12201 DIO)/Bank 0/Port 0/Line 3/Direction | I23: ="IO" & A20 -> IO4
C24: ="PXI 10-100-001/SPDT" & D24 -> PXI 10-100-001/SPDT4 | D24: =D18+1 -> 4 | E24: =E18 -> DO (SPDT) | F24: =F18 -> Select_DO | G24: =IF(OR(F24="None",F24="TBD"),"None",_xlfn.CONCAT("ATE/",I24,"/",F24)) -> ATE/IO4/Select_DO | H24: =Paths!$B$12 & D24 -> Targets/Controller/Custom Devices/PickeringSwitching/Subunit1/Switch1_4 | I24: ="IO" & A20 -> IO4
C25: ="PXI-2510-1/dut" & D25 -> PXI-2510-1/dut3 | D25: =D19+1 -> 3 | E25: =E19 -> FIU | F25: =F19 -> TBD | G25: =IF(OR(F25="None",F25="TBD"),"None",_xlfn.CONCAT("ATE/",I25,"/",F25)) -> None | H25: TBD | I25: ="IO" & A20 -> IO4
A26: =A20+1 -> 5 | B26: =B20 -> AO/DO AO U: 0-10 V DO: 0-Vsup | C26: ="PXIe-6738/AO" & D26 -> PXIe-6738/AO4 | D26: =D20+1 -> 4 | E26: =E20 -> Voltage out 0-10 V | F26: =F20 -> AO | G26: =IF(OR(F26="None",F26="TBD"),"None",_xlfn.CONCAT("ATE/",I26,"/",F26)) -> ATE/IO5/AO | H26: =Paths!$B$26 & D26 -> Targets/Controller/Hardware/Chassis/DAQ/PXI1Slot15/Analog Output/AO4 | I26: ="IO" & A26 -> IO5 | J26: Ax.x | K26: Bx.x
C27: ="PXIe-7820R/DIO" & D27 -> PXIe-7820R/DIO4 | D27: =D21+1 -> 4 | E27: =E21 -> FPGA DO (PWM Gen.) | F27: =F21 -> PWM_FR | G27: =IF(OR(F27="None",F27="TBD"),"None",_xlfn.CONCAT("ATE/",I27,"/",F27)) -> ATE/IO5/PWM_FR | H27: =Paths!$B$2 & I27 & Paths!$B$6 -> Targets/Controller/Custom Devices/FPGA Addon/Scalars/Scalar Outputs/PWM.Out.IO5/FREQ | I27: ="IO" & A26 -> IO5
C28: ="PXIe-7820R/DIO" & D28 -> PXIe-7820R/DIO4 | D28: =D22+1 -> 4 | E28: =E22 -> FPGA DO (PWM Gen.) | F28: =F22 -> PWM_DC | G28: =IF(OR(F28="None",F28="TBD"),"None",_xlfn.CONCAT("ATE/",I28,"/",F28)) -> ATE/IO5/PWM_DC | H28: =Paths!$B$2 & I28 & Paths!$B$7 -> Targets/Controller/Custom Devices/FPGA Addon/Scalars/Scalar Outputs/PWM.Out.IO5/DC | I28: ="IO" & A26 -> IO5
C29: ="SLSC-12201-1/P" & ROUNDDOWN(D29/8,0) & "." & MOD(D29,8) -> SLSC-12201-1/P0.4 | D29: =D23+1 -> 4 | E29: =E23 -> Output Push-Pull | F29: =F23 -> None | G29: =IF(OR(F29="None",F29="TBD"),"None",_xlfn.CONCAT("ATE/",I29,"/",F29)) -> None | H29: =Paths!$B$19 & "Bank " & ROUNDDOWN(D29/16,0) & "/Port " & ROUNDDOWN(D29/8,0) & "/Line " &MOD(D29,8) &"/Direction" -> Targets/Controller/Hardware/SLSC/SLSC Chassis/Modules/Slot 8 (SLSC-12201 DIO)/Bank 0/Port 0/Line 4/Direction | I29: ="IO" & A26 -> IO5
C30: ="PXI 10-100-001/SPDT" & D30 -> PXI 10-100-001/SPDT5 | D30: =D24+1 -> 5 | E30: =E24 -> DO (SPDT) | F30: =F24 -> Select_DO | G30: =IF(OR(F30="None",F30="TBD"),"None",_xlfn.CONCAT("ATE/",I30,"/",F30)) -> ATE/IO5/Select_DO | H30: =Paths!$B$12 & D30 -> Targets/Controller/Custom Devices/PickeringSwitching/Subunit1/Switch1_5 | I30: ="IO" & A26 -> IO5
C31: ="PXI-2510-1/dut" & D31 -> PXI-2510-1/dut4 | D31: =D25+1 -> 4 | E31: =E25 -> FIU | F31: =F25 -> TBD | G31: =IF(OR(F31="None",F31="TBD"),"None",_xlfn.CONCAT("ATE/",I31,"/",F31)) -> None | H31: TBD | I31: ="IO" & A26 -> IO5
A32: =A26+1 -> 6 | B32: =B26 -> AO/DO AO U: 0-10 V DO: 0-Vsup | C32: ="PXIe-6738/AO" & D32 -> PXIe-6738/AO5 | D32: =D26+1 -> 5 | E32: =E26 -> Voltage out 0-10 V | F32: =F26 -> AO | G32: =IF(OR(F32="None",F32="TBD"),"None",_xlfn.CONCAT("ATE/",I32,"/",F32)) -> ATE/IO6/AO | H32: =Paths!$B$26 & D32 -> Targets/Controller/Hardware/Chassis/DAQ/PXI1Slot15/Analog Output/AO5 | I32: ="IO" & A32 -> IO6 | J32: Ax.x | K32: Bx.x
C33: ="PXIe-7820R/DIO" & D33 -> PXIe-7820R/DIO5 | D33: =D27+1 -> 5 | E33: =E27 -> FPGA DO (PWM Gen.) | F33: =F27 -> PWM_FR | G33: =IF(OR(F33="None",F33="TBD"),"None",_xlfn.CONCAT("ATE/",I33,"/",F33)) -> ATE/IO6/PWM_FR | H33: =Paths!$B$2 & I33 & Paths!$B$6 -> Targets/Controller/Custom Devices/FPGA Addon/Scalars/Scalar Outputs/PWM.Out.IO6/FREQ | I33: ="IO" & A32 -> IO6
C34: ="PXIe-7820R/DIO" & D34 -> PXIe-7820R/DIO5 | D34: =D28+1 -> 5 | E34: =E28 -> FPGA DO (PWM Gen.) | F34: =F28 -> PWM_DC | G34: =IF(OR(F34="None",F34="TBD"),"None",_xlfn.CONCAT("ATE/",I34,"/",F34)) -> ATE/IO6/PWM_DC | H34: =Paths!$B$2 & I34 & Paths!$B$7 -> Targets/Controller/Custom Devices/FPGA Addon/Scalars/Scalar Outputs/PWM.Out.IO6/DC | I34: ="IO" & A32 -> IO6
C35: ="SLSC-12201-1/P" & ROUNDDOWN(D35/8,0) & "." & MOD(D35,8) -> SLSC-12201-1/P0.5 | D35: =D29+1 -> 5 | E35: =E29 -> Output Push-Pull | F35: =F29 -> None | G35: =IF(OR(F35="None",F35="TBD"),"None",_xlfn.CONCAT("ATE/",I35,"/",F35)) -> None | H35: =Paths!$B$19 & "Bank " & ROUNDDOWN(D35/16,0) & "/Port " & ROUNDDOWN(D35/8,0) & "/Line " &MOD(D35,8) &"/Direction" -> Targets/Controller/Hardware/SLSC/SLSC Chassis/Modules/Slot 8 (SLSC-12201 DIO)/Bank 0/Port 0/Line 5/Direction | I35: ="IO" & A32 -> IO6
C36: ="PXI 10-100-001/SPDT" & D36 -> PXI 10-100-001/SPDT6 | D36: =D30+1 -> 6 | E36: =E30 -> DO (SPDT) | F36: =F30 -> Select_DO | G36: =IF(OR(F36="None",F36="TBD"),"None",_xlfn.CONCAT("ATE/",I36,"/",F36)) -> ATE/IO6/Select_DO | H36: =Paths!$B$12 & D36 -> Targets/Controller/Custom Devices/PickeringSwitching/Subunit1/Switch1_6 | I36: ="IO" & A32 -> IO6
C37: ="PXI-2510-1/dut" & D37 -> PXI-2510-1/dut5 | D37: =D31+1 -> 5 | E37: =E31 -> FIU | F37: =F31 -> TBD | G37: =IF(OR(F37="None",F37="TBD"),"None",_xlfn.CONCAT("ATE/",I37,"/",F37)) -> None | H37: TBD | I37: ="IO" & A32 -> IO6
A38: =A32+1 -> 7 | B38: =B32 -> AO/DO AO U: 0-10 V DO: 0-Vsup | C38: ="PXIe-6738/AO" & D38 -> PXIe-6738/AO6 | D38: =D32+1 -> 6 | E38: =E32 -> Voltage out 0-10 V | F38: =F32 -> AO | G38: =IF(OR(F38="None",F38="TBD"),"None",_xlfn.CONCAT("ATE/",I38,"/",F38)) -> ATE/IO7/AO | H38: =Paths!$B$26 & D38 -> Targets/Controller/Hardware/Chassis/DAQ/PXI1Slot15/Analog Output/AO6 | I38: ="IO" & A38 -> IO7 | J38: Ax.x | K38: Bx.x
C39: ="PXIe-7820R/DIO" & D39 -> PXIe-7820R/DIO6 | D39: =D33+1 -> 6 | E39: =E33 -> FPGA DO (PWM Gen.) | F39: =F33 -> PWM_FR | G39: =IF(OR(F39="None",F39="TBD"),"None",_xlfn.CONCAT("ATE/",I39,"/",F39)) -> ATE/IO7/PWM_FR | H39: =Paths!$B$2 & I39 & Paths!$B$6 -> Targets/Controller/Custom Devices/FPGA Addon/Scalars/Scalar Outputs/PWM.Out.IO7/FREQ | I39: ="IO" & A38 -> IO7
C40: ="PXIe-7820R/DIO" & D40 -> PXIe-7820R/DIO6 | D40: =D34+1 -> 6 | E40: =E34 -> FPGA DO (PWM Gen.) | F40: =F34 -> PWM_DC | G40: =IF(OR(F40="None",F40="TBD"),"None",_xlfn.CONCAT("ATE/",I40,"/",F40)) -> ATE/IO7/PWM_DC | H40: =Paths!$B$2 & I40 & Paths!$B$7 -> Targets/Controller/Custom Devices/FPGA Addon/Scalars/Scalar Outputs/PWM.Out.IO7/DC | I40: ="IO" & A38 -> IO7
...

Sheet Paths
A1: These are used for creating VeriStand channel paths in EpecBaseProject-sheet | C1: TODO
A2: PXIe-7820R PWM Out | B2: Targets/Controller/Custom Devices/FPGA Addon/Scalars/Scalar Outputs/PWM.Out.
A3: PXIe-7820R DI | B3: Targets/Controller/Custom Devices/FPGA Addon/Scalars/Scalar Inputs/DI.
A4: PXIe-7820R PWM In | B4: Targets/Controller/Custom Devices/FPGA Addon/Scalars/Scalar Inputs/PWM.In.
A5: PXIe-7820R PWM Set | B5: Targets/Controller/Custom Devices/FPGA Addon/Scalars/Scalar Outputs/PWM.Set.
A6: FPGA DO Frequency | B6: /FREQ
A7: FPGA DO Duty-cycle | B7: /DC
A8: FPGA DI Status | B8: /STATE
A9: FPGA DI Frequency | B9: /FREQ
A10: FPGA DI Duty-cycle | B10: /DC
A11: FPGA DI Timeout | B11: /TIMEOUT
A12: SPDT 40-100-001 | B12: Targets/Controller/Custom Devices/PickeringSwitching/Subunit1/Switch1_
A13: SLSC-12251-1 | B13: Targets/Controller/Hardware/SLSC/SLSC Chassis/Modules/Slot 1 (SLSC EDS :: SLSC-12251)/Physical Channels/Channel_ | C13: Korttityyppiä ei vielä ole --> Ei tietoa tarkasta polusta
A14: SLSC-12251-2 | B14: Targets/Controller/Hardware/SLSC/SLSC Chassis/Modules/Slot 2 (SLSC EDS :: SLSC-12251)/Physical Channels/Channel_ | C14: Korttityyppiä ei vielä ole --> Ei tietoa tarkasta polusta
A15: SLSC-12251-3 | B15: Targets/Controller/Hardware/SLSC/SLSC Chassis/Modules/Slot 3 (SLSC EDS :: SLSC-12251)/Physical Channels/Channel_ | C15: Korttityyppiä ei vielä ole --> Ei tietoa tarkasta polusta
A16: SLSC-12251-4 | B16: Targets/Controller/Hardware/SLSC/SLSC Chassis/Modules/Slot 4 (SLSC EDS :: SLSC-12251)/Physical Channels/Channel_ | C16: Korttityyppiä ei vielä ole --> Ei tietoa tarkasta polusta
A17: SLSC-12202-1 | B17: Targets/Controller/Hardware/SLSC/SLSC Chassis/Modules/Slot 6 (SLSC EDS)/Physical Channels/
A18: SLSC-12202-2 | B18: Targets/Controller/Hardware/SLSC/SLSC Chassis/Modules/Slot 7 (SLSC EDS)/Physical Channels/
A19: SLSC-12201-1 | B19: Targets/Controller/Hardware/SLSC/SLSC Chassis/Modules/Slot 8 (SLSC-12201 DIO)/
A20: SLSC-12201-2 | B20: Targets/Controller/Hardware/SLSC/SLSC Chassis/Modules/Slot 9 (SLSC-12201 DIO)/
A21: PXIe-6375 | B21: Targets/Controller/Hardware/Chassis/DAQ/PXI1Slot3/Analog Input/AI
A22: PXIe-4322-1 | B22: Targets/Controller/Hardware/Chassis/DAQ/PXI1Slot11/Analog Output/AO
A23: PXIe-4322-2 | B23: Targets/Controller/Hardware/Chassis/DAQ/PXI1Slot12/Analog Output/AO
A24: PXIe-4322-3 | B24: Targets/Controller/Hardware/Chassis/DAQ/PXI1Slot13/Analog Output/AO
A25: PXIe-4322-4 | B25: Targets/Controller/Hardware/Chassis/DAQ/PXI1Slot14/Analog Output/AO
A26: PXIe-6738 | B26: Targets/Controller/Hardware/Chassis/DAQ/PXI1Slot15/Analog Output/AO | C26: Korttityyppiä ei vielä ole --> Ei tietoa tarkasta polusta
A27: Scaled IO values | B27: Targets/Controller/Calculated Channels/ATE/ | C27: Ei lukkoon lyöty tapa lisätä "Calculated Channels" -kanavia
A28: Scaled voltage | B28: /AI | C28: Ei lukkoon lyöty tapa lisätä "Calculated Channels" -kanavia
A29: Scaled current | B29: /AI | C29: Ei lukkoon lyöty tapa lisätä "Calculated Channels" -kanavia
A30: RMX Controls | B30: Targets/Controller/Custom Devices/RMXVisaControl/Controls/
A31: RMX Indicators | B31: Targets/Controller/Custom Devices/RMXVisaControl/Indicators/
A32: PXI-2567 | B32: Targets/Controller/Hardware/Chassis/DAQ/PXI1Slot5/Digital Output/
B36: Targets/Controller/Hardware/SLSC/SLSC Chassis/Modules/Slot 6 (SLSC EDS)/Commands/NI.UpdateChannelConfiguration
B38: Targets/Controller/Hardware/SLSC/SLSC Chassis/Modules/Slot 6 (SLSC EDS)/Physical Channels/port0//line0/Properties/NI.Line.Direction
B39: Targets/Controller/Hardware/SLSC/SLSC Chassis/Modules/Slot 6 (SLSC EDS)/Physical Channels/port0//line0/Properties/NI.Line.Direction

Sheet Aliases
A1: {=AliasPaths} -> VeriStand Alias Path | B1: {=ChannelPaths} -> VeriStand Channel path | D1: These are updated from EpecBaseProject-sheet
A2: ATE/IO1/AO | B2: Targets/Controller/Hardware/Chassis/DAQ/PXI1Slot15/Analog Output/AO0 | D2: DO NOT EDIT !
A3: ATE/IO1/PWM_FR | B3: Targets/Controller/Custom Devices/FPGA Addon/Scalars/Scalar Outputs/PWM.Out.IO1/FREQ
A4: ATE/IO1/PWM_DC | B4: Targets/Controller/Custom Devices/FPGA Addon/Scalars/Scalar Outputs/PWM.Out.IO1/DC
A5: None | B5: Targets/Controller/Hardware/SLSC/SLSC Chassis/Modules/Slot 8 (SLSC-12201 DIO)/Bank 0/Port 0/Line 0/Direction
A6: ATE/IO1/Select_DO | B6: Targets/Controller/Custom Devices/PickeringSwitching/Subunit1/Switch1_1
A7: None | B7: TBD
A8: ATE/IO2/AO | B8: Targets/Controller/Hardware/Chassis/DAQ/PXI1Slot15/Analog Output/AO1
A9: ATE/IO2/PWM_FR | B9: Targets/Controller/Custom Devices/FPGA Addon/Scalars/Scalar Outputs/PWM.Out.IO2/FREQ
A10: ATE/IO2/PWM_DC | B10: Targets/Controller/Custom Devices/FPGA Addon/Scalars/Scalar Outputs/PWM.Out.IO2/DC
A11: None | B11: Targets/Controller/Hardware/SLSC/SLSC Chassis/Modules/Slot 8 (SLSC-12201 DIO)/Bank 0/Port 0/Line 1/Direction
A12: ATE/IO2/Select_DO | B12: Targets/Controller/Custom Devices/PickeringSwitching/Subunit1/Switch1_2
A13: None | B13: TBD
A14: ATE/IO3/AO | B14: Targets/Controller/Hardware/Chassis/DAQ/PXI1Slot15/Analog Output/AO2
... A97: None | B97: TBD
A98: 0 | B98: 0
A99: ATE/IO17/AO | B99: Targets/Controller/Hardware/Chassis/DAQ/PXI1Slot15/Analog Output/AO16
A100: ATE/IO17/PWM_FR | B100: Targets/Controller/Custom Devices/FPGA Addon/Scalars/Scalar Outputs/PWM.Out.IO17/FREQ
A101: ATE/IO17/PWM_DC | B101: Targets/Controller/Custom Devices/FPGA Addon/Scalars/Scalar Outputs/PWM.Out.IO17/DC
A102: None | B102: Targets/Controller/Hardware/SLSC/SLSC Chassis/Modules/Slot 8 (SLSC-12201 DIO)/Bank 1/Port 2/Line 0/Direction
A103: None | B103: TBD
A104: ATE/IO17/Select_DO_or_AOR | B104: Targets/Controller/Custom Devices/PickeringSwitching/Subunit1/Switch1_17
A105: ATE/IO17/Select_AOR | B105: Targets/Controller/Custom Devices/PickeringSwitching/Subunit1/Switch1_18
A106: None | B106: TBD
A107: ATE/IO18/AO | B107: Targets/Controller/Hardware/Chassis/DAQ/PXI1Slot15/Analog Output/AO17
A108: ATE/IO18/PWM_FR | B108: Targets/Controller/Custom Devices/FPGA Addon/Scalars/Scalar Outputs/PWM.Out.IO18/FREQ
A109: ATE/IO18/PWM_DC | B109: Targets/Controller/Custom Devices/FPGA Addon/Scalars/Scalar Outputs/PWM.Out.IO18/DC
A110: None | B110: Targets/Controller/Hardware/SLSC/SLSC Chassis/Modules/Slot 8 (SLSC-12201 DIO)/Bank 1/Port 2/Line 1/Direction
... A226: None | B226: TBD
A227: 0 | B227: 0
A228: ATE/IO33/AO | B228: Targets/Controller/Hardware/Chassis/DAQ/PXI1Slot11/Analog Output/AO0
A229: None | B229: TBD
A230: ATE/IO33/Select_AOR | B230: Targets/Controller/Custom Devices/PickeringSwitching/Subunit1/Switch1_51
A231: None | B231: TBD
A232: ATE/IO34/AO | B232: Targets/Controller/Hardware/Chassis/DAQ/PXI1Slot11/Analog Output/AO1
A233: None | B233: TBD
A234: ATE/IO34/Select_AOR | B234: Targets/Controller/Custom Devices/PickeringSwitching/Subunit1/Switch1_52
A235: None | B235: TBD
A236: ATE/IO35/AO | B236: Targets/Controller/Hardware/Chassis/DAQ/PXI1Slot11/Analog Output/AO2
A237: None | B237: TBD
...
